log/output_50_2022_Attention_gpu2.log
wandb: Currently logged in as: pqy000 (pqythu). Use `wandb login --relogin` to force relogin
GPU device ID: 2
newdata/50_2022.npy
0
2024-09-07 12:09:30.628734: I tensorflow/core/platform/cpu_feature_guard.cc:193] This TensorFlow binary is optimized with oneAPI Deep Neural Network Library (oneDNN) to use the following CPU instructions in performance-critical operations:  AVX2 FMA
To enable them in other operations, rebuild TensorFlow with the appropriate compiler flags.
wandb: wandb version 0.17.9 is available!  To upgrade, please run:
wandb:  $ pip install wandb --upgrade
wandb: Tracking run with wandb version 0.12.17
wandb: Run data is saved locally in /home/qingyi/GPU20/DeepLOB/wandb/run-20240907_120919-2b4u91wc
wandb: Run `wandb offline` to turn off syncing.
wandb: Syncing run Attention
wandb: ⭐️ View project at https://wandb.ai/pqythu/futures50
wandb: 🚀 View run at https://wandb.ai/pqythu/futures50/runs/2b4u91wc
2024-09-07 12:09:31.651674: W tensorflow/compiler/xla/stream_executor/platform/default/dso_loader.cc:64] Could not load dynamic library 'libnvinfer.so.7'; dlerror: libnvinfer.so.7: cannot open shared object file: No such file or directory; LD_LIBRARY_PATH: /opt/cudnn/lib64:/usr/local/cuda/lib64
2024-09-07 12:09:31.651792: W tensorflow/compiler/xla/stream_executor/platform/default/dso_loader.cc:64] Could not load dynamic library 'libnvinfer_plugin.so.7'; dlerror: libnvinfer_plugin.so.7: cannot open shared object file: No such file or directory; LD_LIBRARY_PATH: /opt/cudnn/lib64:/usr/local/cuda/lib64
2024-09-07 12:09:31.651805: W tensorflow/compiler/tf2tensorrt/utils/py_utils.cc:38] TF-TRT Warning: Cannot dlopen some TensorRT libraries. If you would like to use Nvidia GPU with TensorRT, please make sure the missing libraries mentioned above are installed properly.
Model(
  (attn): MultiheadAttention(
    (out_proj): NonDynamicallyQuantizableLinear(in_features=10, out_features=10, bias=True)
  )
  (fc): Linear(in_features=10, out_features=5, bias=True)
)
number of parameters: 495
Training start
epoch  1 | time used:  0.79s | train_loss 1.492 | valid loss 1.634 | valid acc 0.175 | mae 2.328 | mse 7.543 | rmse 2.75 | r2 -2.55 | sharp 2.72
epoch  2 | time used:  0.09s | train_loss 1.480 | valid loss 1.633 | valid acc 0.175 | mae 2.328 | mse 7.543 | rmse 2.75 | r2 -2.55 | sharp 2.72
epoch  3 | time used:  0.08s | train_loss 1.481 | valid loss 1.480 | valid acc 0.325 | mae 1.673 | mse 4.923 | rmse 2.22 | r2 -1.32 | sharp 0.00
epoch  4 | time used:  0.08s | train_loss 1.492 | valid loss 1.479 | valid acc 0.325 | mae 1.673 | mse 4.923 | rmse 2.22 | r2 -1.32 | sharp 0.00
epoch  5 | time used:  0.08s | train_loss 1.493 | valid loss 1.480 | valid acc 0.325 | mae 1.673 | mse 4.923 | rmse 2.22 | r2 -1.32 | sharp 0.00
epoch  6 | time used:  0.09s | train_loss 1.484 | valid loss 1.479 | valid acc 0.325 | mae 1.673 | mse 4.923 | rmse 2.22 | r2 -1.32 | sharp 0.00
epoch  7 | time used:  0.09s | train_loss 1.489 | valid loss 1.479 | valid acc 0.325 | mae 1.673 | mse 4.923 | rmse 2.22 | r2 -1.32 | sharp 0.00
epoch  8 | time used:  0.09s | train_loss 1.487 | valid loss 1.479 | valid acc 0.325 | mae 1.673 | mse 4.923 | rmse 2.22 | r2 -1.32 | sharp 0.00
epoch  9 | time used:  0.09s | train_loss 1.490 | valid loss 1.479 | valid acc 0.325 | mae 1.673 | mse 4.923 | rmse 2.22 | r2 -1.32 | sharp 0.00
epoch 10 | time used:  0.10s | train_loss 1.498 | valid loss 1.634 | valid acc 0.175 | mae 2.328 | mse 7.543 | rmse 2.75 | r2 -2.55 | sharp 2.72
saving the model to ./save/2022_50/Attention/checkpoint10.pt
epoch 11 | time used:  0.11s | train_loss 1.485 | valid loss 1.634 | valid acc 0.175 | mae 2.328 | mse 7.543 | rmse 2.75 | r2 -2.55 | sharp 2.72
epoch 12 | time used:  0.11s | train_loss 1.484 | valid loss 1.634 | valid acc 0.175 | mae 2.328 | mse 7.543 | rmse 2.75 | r2 -2.55 | sharp 2.72
epoch 13 | time used:  0.15s | train_loss 1.480 | valid loss 1.633 | valid acc 0.175 | mae 2.328 | mse 7.543 | rmse 2.75 | r2 -2.55 | sharp 2.72
epoch 14 | time used:  0.12s | train_loss 1.484 | valid loss 1.633 | valid acc 0.175 | mae 2.328 | mse 7.543 | rmse 2.75 | r2 -2.55 | sharp 2.72
epoch 15 | time used:  0.11s | train_loss 1.489 | valid loss 1.632 | valid acc 0.175 | mae 2.328 | mse 7.543 | rmse 2.75 | r2 -2.55 | sharp 2.72
epoch 16 | time used:  0.07s | train_loss 1.480 | valid loss 1.633 | valid acc 0.175 | mae 2.328 | mse 7.543 | rmse 2.75 | r2 -2.55 | sharp 2.72
epoch 17 | time used:  0.08s | train_loss 1.484 | valid loss 1.618 | valid acc 0.175 | mae 2.328 | mse 7.543 | rmse 2.75 | r2 -2.55 | sharp 2.72
epoch 18 | time used:  0.09s | train_loss 1.487 | valid loss 1.634 | valid acc 0.175 | mae 2.328 | mse 7.543 | rmse 2.75 | r2 -2.55 | sharp 2.72
epoch 19 | time used:  0.09s | train_loss 1.478 | valid loss 1.571 | valid acc 0.175 | mae 2.328 | mse 7.543 | rmse 2.75 | r2 -2.55 | sharp 2.72
epoch 20 | time used:  0.08s | train_loss 1.500 | valid loss 1.479 | valid acc 0.325 | mae 1.673 | mse 4.923 | rmse 2.22 | r2 -1.32 | sharp 0.00
saving the model to ./save/2022_50/Attention/checkpoint20.pt
epoch 21 | time used:  0.08s | train_loss 1.489 | valid loss 1.479 | valid acc 0.325 | mae 1.673 | mse 4.923 | rmse 2.22 | r2 -1.32 | sharp 0.00
epoch 22 | time used:  0.07s | train_loss 1.490 | valid loss 1.479 | valid acc 0.325 | mae 1.673 | mse 4.923 | rmse 2.22 | r2 -1.32 | sharp 0.00
epoch 23 | time used:  0.07s | train_loss 1.490 | valid loss 1.479 | valid acc 0.325 | mae 1.673 | mse 4.923 | rmse 2.22 | r2 -1.32 | sharp 0.00
epoch 24 | time used:  0.14s | train_loss 1.495 | valid loss 1.479 | valid acc 0.325 | mae 1.673 | mse 4.923 | rmse 2.22 | r2 -1.32 | sharp 0.00
epoch 25 | time used:  0.08s | train_loss 1.497 | valid loss 1.480 | valid acc 0.325 | mae 1.673 | mse 4.923 | rmse 2.22 | r2 -1.32 | sharp 0.00
epoch 26 | time used:  0.07s | train_loss 1.491 | valid loss 1.479 | valid acc 0.325 | mae 1.673 | mse 4.923 | rmse 2.22 | r2 -1.32 | sharp 0.00
epoch 27 | time used:  0.07s | train_loss 1.493 | valid loss 1.480 | valid acc 0.325 | mae 1.673 | mse 4.923 | rmse 2.22 | r2 -1.32 | sharp 0.00
epoch 28 | time used:  0.08s | train_loss 1.497 | valid loss 1.480 | valid acc 0.325 | mae 1.673 | mse 4.923 | rmse 2.22 | r2 -1.32 | sharp 0.00
epoch 29 | time used:  0.09s | train_loss 1.492 | valid loss 1.479 | valid acc 0.325 | mae 1.673 | mse 4.923 | rmse 2.22 | r2 -1.32 | sharp 0.00
epoch 30 | time used:  0.07s | train_loss 1.486 | valid loss 1.634 | valid acc 0.175 | mae 2.328 | mse 7.543 | rmse 2.75 | r2 -2.55 | sharp 2.72
saving the model to ./save/2022_50/Attention/checkpoint30.pt
epoch 31 | time used:  0.09s | train_loss 1.485 | valid loss 1.634 | valid acc 0.175 | mae 2.328 | mse 7.543 | rmse 2.75 | r2 -2.55 | sharp 2.72
epoch 32 | time used:  0.08s | train_loss 1.485 | valid loss 1.634 | valid acc 0.175 | mae 2.328 | mse 7.543 | rmse 2.75 | r2 -2.55 | sharp 2.72
epoch 33 | time used:  0.08s | train_loss 1.480 | valid loss 1.634 | valid acc 0.175 | mae 2.328 | mse 7.543 | rmse 2.75 | r2 -2.55 | sharp 2.72
epoch 34 | time used:  0.07s | train_loss 1.483 | valid loss 1.633 | valid acc 0.175 | mae 2.328 | mse 7.543 | rmse 2.75 | r2 -2.55 | sharp 2.72
epoch 35 | time used:  0.07s | train_loss 1.481 | valid loss 1.633 | valid acc 0.175 | mae 2.328 | mse 7.543 | rmse 2.75 | r2 -2.55 | sharp 2.72
epoch 36 | time used:  0.08s | train_loss 1.487 | valid loss 1.633 | valid acc 0.175 | mae 2.328 | mse 7.543 | rmse 2.75 | r2 -2.55 | sharp 2.72
epoch 37 | time used:  0.09s | train_loss 1.485 | valid loss 1.633 | valid acc 0.175 | mae 2.328 | mse 7.543 | rmse 2.75 | r2 -2.55 | sharp 2.72
epoch 38 | time used:  0.10s | train_loss 1.483 | valid loss 1.633 | valid acc 0.175 | mae 2.328 | mse 7.543 | rmse 2.75 | r2 -2.55 | sharp 2.72
epoch 39 | time used:  0.11s | train_loss 1.481 | valid loss 1.633 | valid acc 0.175 | mae 2.328 | mse 7.543 | rmse 2.75 | r2 -2.55 | sharp 2.72
epoch 40 | time used:  0.11s | train_loss 1.484 | valid loss 1.633 | valid acc 0.175 | mae 2.328 | mse 7.543 | rmse 2.75 | r2 -2.55 | sharp 2.72
