log/output_50_2022_Attention_gpu3.log
wandb: Currently logged in as: pqy000 (pqythu). Use `wandb login --relogin` to force relogin
GPU device ID: 3
newdata/50_2022.npy
0
2024-09-07 11:35:14.460125: I tensorflow/core/platform/cpu_feature_guard.cc:193] This TensorFlow binary is optimized with oneAPI Deep Neural Network Library (oneDNN) to use the following CPU instructions in performance-critical operations:  AVX2 FMA
To enable them in other operations, rebuild TensorFlow with the appropriate compiler flags.
2024-09-07 11:35:15.435358: W tensorflow/compiler/xla/stream_executor/platform/default/dso_loader.cc:64] Could not load dynamic library 'libnvinfer.so.7'; dlerror: libnvinfer.so.7: cannot open shared object file: No such file or directory; LD_LIBRARY_PATH: /opt/cudnn/lib64:/usr/local/cuda/lib64
2024-09-07 11:35:15.435465: W tensorflow/compiler/xla/stream_executor/platform/default/dso_loader.cc:64] Could not load dynamic library 'libnvinfer_plugin.so.7'; dlerror: libnvinfer_plugin.so.7: cannot open shared object file: No such file or directory; LD_LIBRARY_PATH: /opt/cudnn/lib64:/usr/local/cuda/lib64
2024-09-07 11:35:15.438913: W tensorflow/compiler/tf2tensorrt/utils/py_utils.cc:38] TF-TRT Warning: Cannot dlopen some TensorRT libraries. If you would like to use Nvidia GPU with TensorRT, please make sure the missing libraries mentioned above are installed properly.
wandb: wandb version 0.17.9 is available!  To upgrade, please run:
wandb:  $ pip install wandb --upgrade
wandb: Tracking run with wandb version 0.12.17
wandb: Run data is saved locally in /home/qingyi/GPU20/DeepLOB/wandb/run-20240907_113510-32ekmrm7
wandb: Run `wandb offline` to turn off syncing.
wandb: Syncing run Attention
wandb: ⭐️ View project at https://wandb.ai/pqythu/futures50
wandb: 🚀 View run at https://wandb.ai/pqythu/futures50/runs/32ekmrm7
Model(
  (attn): MultiheadAttention(
    (out_proj): NonDynamicallyQuantizableLinear(in_features=10, out_features=10, bias=True)
  )
  (fc): Linear(in_features=10, out_features=5, bias=True)
)
number of parameters: 495
Training start
epoch  1 | time used:  0.77s | train_loss 1.408 | valid loss 1.480 | valid acc 0.359 | mae 2.027 | mse 7.178 | rmse 2.68 | r2 -1.34 | sharp 1.53
epoch  2 | time used:  0.20s | train_loss 1.407 | valid loss 1.463 | valid acc 0.375 | mae 1.972 | mse 6.957 | rmse 2.64 | r2 -1.27 | sharp 0.00
epoch  3 | time used:  0.13s | train_loss 1.544 | valid loss 1.464 | valid acc 0.375 | mae 1.972 | mse 6.957 | rmse 2.64 | r2 -1.27 | sharp 0.00
epoch  4 | time used:  0.14s | train_loss 1.534 | valid loss 1.464 | valid acc 0.375 | mae 1.972 | mse 6.957 | rmse 2.64 | r2 -1.27 | sharp 0.00
epoch  5 | time used:  0.14s | train_loss 1.539 | valid loss 1.464 | valid acc 0.375 | mae 1.972 | mse 6.957 | rmse 2.64 | r2 -1.27 | sharp 0.00
epoch  6 | time used:  0.14s | train_loss 1.430 | valid loss 1.481 | valid acc 0.359 | mae 2.027 | mse 7.178 | rmse 2.68 | r2 -1.34 | sharp 1.53
epoch  7 | time used:  0.21s | train_loss 1.397 | valid loss 1.480 | valid acc 0.359 | mae 2.027 | mse 7.178 | rmse 2.68 | r2 -1.34 | sharp 1.53
epoch  8 | time used:  0.13s | train_loss 1.397 | valid loss 1.480 | valid acc 0.359 | mae 2.027 | mse 7.178 | rmse 2.68 | r2 -1.34 | sharp 1.53
epoch  9 | time used:  0.13s | train_loss 1.397 | valid loss 1.481 | valid acc 0.359 | mae 2.027 | mse 7.178 | rmse 2.68 | r2 -1.34 | sharp 1.53
epoch 10 | time used:  0.14s | train_loss 1.399 | valid loss 1.481 | valid acc 0.359 | mae 2.027 | mse 7.178 | rmse 2.68 | r2 -1.34 | sharp 1.53
saving the model to ./save/2022_50/Attention/checkpoint10.pt
epoch 11 | time used:  0.16s | train_loss 1.395 | valid loss 1.477 | valid acc 0.359 | mae 2.027 | mse 7.178 | rmse 2.68 | r2 -1.34 | sharp 1.53
epoch 12 | time used:  0.16s | train_loss 1.399 | valid loss 1.480 | valid acc 0.359 | mae 2.027 | mse 7.178 | rmse 2.68 | r2 -1.34 | sharp 1.53
epoch 13 | time used:  0.16s | train_loss 1.399 | valid loss 1.480 | valid acc 0.359 | mae 2.027 | mse 7.178 | rmse 2.68 | r2 -1.34 | sharp 1.53
epoch 14 | time used:  0.18s | train_loss 1.398 | valid loss 1.480 | valid acc 0.359 | mae 2.027 | mse 7.178 | rmse 2.68 | r2 -1.34 | sharp 1.53
epoch 15 | time used:  0.15s | train_loss 1.402 | valid loss 1.480 | valid acc 0.359 | mae 2.027 | mse 7.178 | rmse 2.68 | r2 -1.34 | sharp 1.53
epoch 16 | time used:  0.13s | train_loss 1.390 | valid loss 1.480 | valid acc 0.359 | mae 2.027 | mse 7.178 | rmse 2.68 | r2 -1.34 | sharp 1.53
epoch 17 | time used:  0.14s | train_loss 1.430 | valid loss 1.463 | valid acc 0.375 | mae 1.972 | mse 6.957 | rmse 2.64 | r2 -1.27 | sharp 0.00
epoch 18 | time used:  0.22s | train_loss 1.535 | valid loss 1.463 | valid acc 0.375 | mae 1.972 | mse 6.957 | rmse 2.64 | r2 -1.27 | sharp 0.00
epoch 19 | time used:  0.13s | train_loss 1.533 | valid loss 1.463 | valid acc 0.375 | mae 1.972 | mse 6.957 | rmse 2.64 | r2 -1.27 | sharp 0.00
epoch 20 | time used:  0.17s | train_loss 1.537 | valid loss 1.463 | valid acc 0.375 | mae 1.972 | mse 6.957 | rmse 2.64 | r2 -1.27 | sharp 0.00
saving the model to ./save/2022_50/Attention/checkpoint20.pt
epoch 21 | time used:  0.16s | train_loss 1.533 | valid loss 1.463 | valid acc 0.375 | mae 1.972 | mse 6.957 | rmse 2.64 | r2 -1.27 | sharp 0.00
epoch 22 | time used:  0.15s | train_loss 1.540 | valid loss 1.464 | valid acc 0.375 | mae 1.972 | mse 6.957 | rmse 2.64 | r2 -1.27 | sharp 0.00
epoch 23 | time used:  0.16s | train_loss 1.536 | valid loss 1.464 | valid acc 0.375 | mae 1.972 | mse 6.957 | rmse 2.64 | r2 -1.27 | sharp 0.00
epoch 24 | time used:  0.17s | train_loss 1.440 | valid loss 1.480 | valid acc 0.359 | mae 2.027 | mse 7.178 | rmse 2.68 | r2 -1.34 | sharp 1.53
epoch 25 | time used:  0.18s | train_loss 1.400 | valid loss 1.478 | valid acc 0.359 | mae 2.027 | mse 7.178 | rmse 2.68 | r2 -1.34 | sharp 1.53
epoch 26 | time used:  0.17s | train_loss 1.391 | valid loss 1.480 | valid acc 0.359 | mae 2.027 | mse 7.178 | rmse 2.68 | r2 -1.34 | sharp 1.53
epoch 27 | time used:  0.19s | train_loss 1.395 | valid loss 1.480 | valid acc 0.359 | mae 2.027 | mse 7.178 | rmse 2.68 | r2 -1.34 | sharp 1.53
epoch 28 | time used:  0.16s | train_loss 1.398 | valid loss 1.479 | valid acc 0.359 | mae 2.027 | mse 7.178 | rmse 2.68 | r2 -1.34 | sharp 1.53
epoch 29 | time used:  0.19s | train_loss 1.397 | valid loss 1.421 | valid acc 0.375 | mae 1.972 | mse 6.957 | rmse 2.64 | r2 -1.27 | sharp 0.00
epoch 30 | time used:  0.17s | train_loss 1.517 | valid loss 1.850 | valid acc 0.134 | mae 1.600 | mse 3.067 | rmse 1.75 | r2 -0.00 | sharp 1.53
saving the model to ./save/2022_50/Attention/checkpoint30.pt
epoch 31 | time used:  0.18s | train_loss 1.836 | valid loss 1.880 | valid acc 0.064 | mae 1.722 | mse 4.013 | rmse 2.00 | r2 -0.31 | sharp 1.53
epoch 32 | time used:  0.20s | train_loss 1.869 | valid loss 1.850 | valid acc 0.134 | mae 1.600 | mse 3.067 | rmse 1.75 | r2 -0.00 | sharp 1.53
epoch 33 | time used:  0.19s | train_loss 1.853 | valid loss 1.850 | valid acc 0.134 | mae 1.600 | mse 3.067 | rmse 1.75 | r2 -0.00 | sharp 1.53
epoch 34 | time used:  0.18s | train_loss 1.852 | valid loss 1.850 | valid acc 0.134 | mae 1.600 | mse 3.067 | rmse 1.75 | r2 -0.00 | sharp 1.53
epoch 35 | time used:  0.18s | train_loss 1.736 | valid loss 1.480 | valid acc 0.359 | mae 2.027 | mse 7.178 | rmse 2.68 | r2 -1.34 | sharp 1.53
epoch 36 | time used:  0.19s | train_loss 1.398 | valid loss 1.480 | valid acc 0.359 | mae 2.027 | mse 7.178 | rmse 2.68 | r2 -1.34 | sharp 1.53
epoch 37 | time used:  0.21s | train_loss 1.395 | valid loss 1.480 | valid acc 0.359 | mae 2.027 | mse 7.178 | rmse 2.68 | r2 -1.34 | sharp 1.53
epoch 38 | time used:  0.27s | train_loss 1.398 | valid loss 1.480 | valid acc 0.359 | mae 2.027 | mse 7.178 | rmse 2.68 | r2 -1.34 | sharp 1.53
epoch 39 | time used:  0.18s | train_loss 1.395 | valid loss 1.480 | valid acc 0.359 | mae 2.027 | mse 7.178 | rmse 2.68 | r2 -1.34 | sharp 1.53
epoch 40 | time used:  0.29s | train_loss 1.399 | valid loss 1.480 | valid acc 0.359 | mae 2.027 | mse 7.178 | rmse 2.68 | r2 -1.34 | sharp 1.53
